---
layout: post
category: WantedPreOnbording
title: 11월 09일 원티드 프리온보딩 백엔드 14일차 TIL
description: >
  django custom command
tags: [WantedPreOnbording, Django]
---
# 11월 09일 원티드 프리온보딩 백엔드 14일차 TIL

- [11월 09일 원티드 프리온보딩 백엔드 14일차 TIL](#11월-09일-원티드-프리온보딩-백엔드-14일차-til)
  - [1️⃣ 진행상황](#1️⃣진행상황)
  - [2️⃣ 진행상황리뷰](#2️⃣진행상황리뷰)
  - [3️⃣ Today I Learned](#3️⃣today-i-learned)
    - [migration 파일](#migration-파일)

## 1️⃣ 진행상황

- 하수 데이터와 강수 데이터를 연계하기 위한 구 모델 생성

## 2️⃣ 진행상황리뷰

```python
# data/models.py

class Gu(models.Model):
    name = models.CharField(max_length=8, verbose_name="구청명", unique=True)
    code = models.SmallIntegerField(verbose_name="구청 코드", unique=True, null=True)
    gubn = models.CharField(max_length=2, verbose_name="구분코드", unique=True, null=True)

class Sewer(models.Model):
    ...
    gu = models.ForeignKey(Gu, on_delete=models.CASCADE, verbose_name="구청")
...
class Rainguage(models.Model):
    ...
    gu = models.ForeignKey(Gu, on_delete=models.CASCADE, verbose_name="구청")

```
- 하수관, 강수량 모델을 연계시키기 위하여 구 모델 생성


## 3️⃣ Today I Learned

### migration 파일

구 모델을 생성하고 평소와 같이 `migrate`를 진행하려 하였으나 다음과 같은 오류가 발생하였다.
```bash
Running migrations:
  Applying < migration 파일 > Traceback (most recent call last):
  File "< Python 설치 디렉토리 >/site-packages/django/db/models/fields/__init__.py", line 2018, in get_prep_value
    return int(value)
ValueError: invalid literal for int() with base 10: ' '

The above exception was the direct cause of the following exception:

Traceback (most recent call last):
  File "< 프로젝트 디렉토리 >/manage.py", line 22, in <module>
    main()
  File "< 프로젝트 디렉토리 >/manage.py", line 18, in main
    execute_from_command_line(sys.argv)
  File "< Python 설치 디렉토리 >/site-packages/django/core/management/__init__.py", line 446, in execute_from_command_line
    utility.execute()
  File "< Python 설치 디렉토리 >/site-packages/django/core/management/__init__.py", line 440, in execute
    self.fetch_command(subcommand).run_from_argv(self.argv)
  File "< Python 설치 디렉토리 >/site-packages/django/core/management/base.py", line 402, in run_from_argv
    self.execute(*args, **cmd_options)
  File "< Python 설치 디렉토리 >/site-packages/django/core/management/base.py", line 448, in execute
    output = self.handle(*args, **options)
  File "< Python 설치 디렉토리 >/site-packages/django/core/management/base.py", line 96, in wrapped
    res = handle_func(*args, **kwargs)
  File "< Python 설치 디렉토리 >/site-packages/django/core/management/commands/migrate.py", line 349, in handle
    post_migrate_state = executor.migrate(
  File "< Python 설치 디렉토리 >/site-packages/django/db/migrations/executor.py", line 135, in migrate
    state = self._migrate_all_forwards(
  File "< Python 설치 디렉토리 >/site-packages/django/db/migrations/executor.py", line 167, in _migrate_all_forwards
    state = self.apply_migration(
  File "< Python 설치 디렉토리 >/site-packages/django/db/migrations/executor.py", line 252, in apply_migration
    state = migration.apply(state, schema_editor)
  File "< Python 설치 디렉토리 >/site-packages/django/db/migrations/migration.py", line 130, in apply
    operation.database_forwards(
  File "< Python 설치 디렉토리 >/site-packages/django/db/migrations/operations/fields.py", line 235, in database_forwards
    schema_editor.alter_field(from_model, from_field, to_field)
  File "< Python 설치 디렉토리 >/site-packages/django/db/backends/sqlite3/schema.py", line 174, in alter_field
    super().alter_field(model, old_field, new_field, strict=strict)
  File "< Python 설치 디렉토리 >/site-packages/django/db/backends/base/schema.py", line 788, in alter_field
    self._alter_field(
  File "< Python 설치 디렉토리 >/site-packages/django/db/backends/sqlite3/schema.py", line 457, in _alter_field
    self._remake_table(model, alter_field=(old_field, new_field))
  File "< Python 설치 디렉토리 >/site-packages/django/db/backends/sqlite3/schema.py", line 248, in _remake_table
    "default": self.prepare_default(self.effective_default(new_field)),
  File "< Python 설치 디렉토리 >/site-packages/django/db/backends/base/schema.py", line 425, in effective_default
    return field.get_db_prep_save(self._effective_default(field), self.connection)
  File "< Python 설치 디렉토리 >/site-packages/django/db/models/fields/related.py", line 1146, in get_db_prep_save
    return self.target_field.get_db_prep_save(value, connection=connection)
  File "< Python 설치 디렉토리 >/site-packages/django/db/models/fields/__init__.py", line 925, in get_db_prep_save
    return self.get_db_prep_value(value, connection=connection, prepared=False)
  File "< Python 설치 디렉토리 >/site-packages/django/db/models/fields/__init__.py", line 2703, in get_db_prep_value
    value = self.get_prep_value(value)
  File "< Python 설치 디렉토리 >/site-packages/django/db/models/fields/__init__.py", line 2020, in get_prep_value
    raise e.__class__(
ValueError: Field 'id' expected a number but got ' '.
```
`id` 값에 숫자가 아닌 문자열이 들어갔다는 에러였다.  
구 모델을 참조하는 다른 모델에서 해당 필드를 `null` 값이 불가능하게 변경했다.  
이 때문에 `makemigrations` 진행 시, 기본 값을 요청했다.  
이때 기본 값을 `' '`로 설정했는데, 이로 인한 문제였던 것 같다.  
이걸 어떻게 고치나 고민을 했는데, 결국 `migrations` 파일 어딘가에 해당 설정이 적혀 있지 않을까 해서 해당 파일을 열어봤다.  
파일 속에는 다음과 같은 내용이 있었다.
```python
...
migrations.AlterField(
    model_name="< 참조 모델 >",
    name="< 참조 모델의 필드 >",
    field=models.ForeignKey(
        default=' ',
        to="< 피참조 모델 >",
        ...
    ),
    preserve_default=False,
),
...
```
`default` 값이 `' '`로 설정되어 있었다.  
그래서 해당 값을 적당한 정수값으로 변경했다. (이번 경우는 구 모델에 총 25개의 레코드가 있어 `26`으로 설정했다.)  
다시 `migrate`를 진행하니 문제없이 마이그레이션이 완료되었다.  
